<?xml version="1.0"?><robot name="pepe">
	<link name="0">
		<visual>
			<geometry>
				<cylinder length="0.05394879835853206" radius="0.09299762538144485"/>
			</geometry>
		</visual>
		<collision>
			<geometry>
				<cylinder length="0.05394879835853206" radius="0.09299762538144485"/>
			</geometry>
		</collision>
		<inertial>
			<mass value="0.0014658021930983149"/>
			<inertia ixx="0.03" iyy="0.03" izz="0.03" ixy="0" ixz="0" iyx="0"/>
		</inertial>
	</link>
	<link name="11">
		<visual>
			<geometry>
				<cylinder length="0.6744894423012142" radius="0.6006934705470675"/>
			</geometry>
		</visual>
		<collision>
			<geometry>
				<cylinder length="0.6744894423012142" radius="0.6006934705470675"/>
			</geometry>
		</collision>
		<inertial>
			<mass value="0.7645939395230764"/>
			<inertia ixx="0.03" iyy="0.03" izz="0.03" ixy="0" ixz="0" iyx="0"/>
		</inertial>
	</link>
	<link name="22">
		<visual>
			<geometry>
				<cylinder length="0.2901679066686532" radius="0.5366765380575591"/>
			</geometry>
		</visual>
		<collision>
			<geometry>
				<cylinder length="0.2901679066686532" radius="0.5366765380575591"/>
			</geometry>
		</collision>
		<inertial>
			<mass value="0.26255752421840395"/>
			<inertia ixx="0.03" iyy="0.03" izz="0.03" ixy="0" ixz="0" iyx="0"/>
		</inertial>
	</link>
	<joint name="11_to_0" type="revolute">
		<parent link="0"/>
		<child link="11"/>
		<axis xyz="1 0 0"/>
		<limit effort="1" upper="-3.1415" lower="3.1415" velocity="1"/>
		<origin rpy="10.406403660353968 4.343300585544596 3.394124561368847" xyz="0.28810973735306966 0.9990231767678343 0.26242701951158987"/>
	</joint>
	<joint name="22_to_11" type="revolute">
		<parent link="11"/>
		<child link="22"/>
		<axis xyz="0 0 1"/>
		<limit effort="1" upper="-3.1415" lower="3.1415" velocity="1"/>
		<origin rpy="0.5054034047412834 6.272133736324706 6.107173761091213" xyz="0.9713647916893305 0.4251201260478199 0.8260852934164531"/>
	</joint>
</robot>
