<?xml version="1.0"?><robot name="pepe">
	<link name="0">
		<visual>
			<geometry>
				<cylinder length="0.5313155137346931" radius="0.016435448932342278"/>
			</geometry>
		</visual>
		<collision>
			<geometry>
				<cylinder length="0.5313155137346931" radius="0.016435448932342278"/>
			</geometry>
		</collision>
		<inertial>
			<mass value="0.000450884714202847"/>
			<inertia ixx="0.03" iyy="0.03" izz="0.03" ixy="0" ixz="0" iyx="0"/>
		</inertial>
	</link>
	<link name="11">
		<visual>
			<geometry>
				<cylinder length="0.6889199180866086" radius="0.8910553853394935"/>
			</geometry>
		</visual>
		<collision>
			<geometry>
				<cylinder length="0.6889199180866086" radius="0.8910553853394935"/>
			</geometry>
		</collision>
		<inertial>
			<mass value="1.718414832372544"/>
			<inertia ixx="0.03" iyy="0.03" izz="0.03" ixy="0" ixz="0" iyx="0"/>
		</inertial>
	</link>
	<link name="22">
		<visual>
			<geometry>
				<cylinder length="0.025028946220423842" radius="0.3557276371384146"/>
			</geometry>
		</visual>
		<collision>
			<geometry>
				<cylinder length="0.025028946220423842" radius="0.3557276371384146"/>
			</geometry>
		</collision>
		<inertial>
			<mass value="0.009950104756698823"/>
			<inertia ixx="0.03" iyy="0.03" izz="0.03" ixy="0" ixz="0" iyx="0"/>
		</inertial>
	</link>
	<link name="23">
		<visual>
			<geometry>
				<cylinder length="0.025028946220423842" radius="0.3557276371384146"/>
			</geometry>
		</visual>
		<collision>
			<geometry>
				<cylinder length="0.025028946220423842" radius="0.3557276371384146"/>
			</geometry>
		</collision>
		<inertial>
			<mass value="0.009950104756698823"/>
			<inertia ixx="0.03" iyy="0.03" izz="0.03" ixy="0" ixz="0" iyx="0"/>
		</inertial>
	</link>
	<link name="24">
		<visual>
			<geometry>
				<cylinder length="0.025028946220423842" radius="0.3557276371384146"/>
			</geometry>
		</visual>
		<collision>
			<geometry>
				<cylinder length="0.025028946220423842" radius="0.3557276371384146"/>
			</geometry>
		</collision>
		<inertial>
			<mass value="0.009950104756698823"/>
			<inertia ixx="0.03" iyy="0.03" izz="0.03" ixy="0" ixz="0" iyx="0"/>
		</inertial>
	</link>
	<link name="25">
		<visual>
			<geometry>
				<cylinder length="0.025028946220423842" radius="0.3557276371384146"/>
			</geometry>
		</visual>
		<collision>
			<geometry>
				<cylinder length="0.025028946220423842" radius="0.3557276371384146"/>
			</geometry>
		</collision>
		<inertial>
			<mass value="0.009950104756698823"/>
			<inertia ixx="0.03" iyy="0.03" izz="0.03" ixy="0" ixz="0" iyx="0"/>
		</inertial>
	</link>
	<joint name="11_to_0" type="revolute">
		<parent link="0"/>
		<child link="11"/>
		<axis xyz="0 0 1"/>
		<limit effort="1" upper="-3.1415" lower="3.1415" velocity="1"/>
		<origin rpy="10.094639952292653 0.8667177131946019 6.063733162780717" xyz="0.7386748357127667 0.1988570307409202 0.6435682235136956"/>
	</joint>
	<joint name="22_to_0" type="revolute">
		<parent link="0"/>
		<child link="22"/>
		<axis xyz="0 0 1"/>
		<limit effort="1" upper="-3.1415" lower="3.1415" velocity="1"/>
		<origin rpy="9.728418724302381 4.60581793149664 5.81330107636588" xyz="0.13574407284830436 0.4047597268960249 0.2676418626192122"/>
	</joint>
	<joint name="23_to_0" type="revolute">
		<parent link="0"/>
		<child link="23"/>
		<axis xyz="0 0 1"/>
		<limit effort="1" upper="-3.1415" lower="3.1415" velocity="1"/>
		<origin rpy="12.971224965736509 4.60581793149664 5.81330107636588" xyz="0.13574407284830436 0.4047597268960249 0.2676418626192122"/>
	</joint>
	<joint name="24_to_0" type="revolute">
		<parent link="0"/>
		<child link="24"/>
		<axis xyz="0 0 1"/>
		<limit effort="1" upper="-3.1415" lower="3.1415" velocity="1"/>
		<origin rpy="16.214031207170635 4.60581793149664 5.81330107636588" xyz="0.13574407284830436 0.4047597268960249 0.2676418626192122"/>
	</joint>
	<joint name="25_to_0" type="revolute">
		<parent link="0"/>
		<child link="25"/>
		<axis xyz="0 0 1"/>
		<limit effort="1" upper="-3.1415" lower="3.1415" velocity="1"/>
		<origin rpy="19.456837448604762 4.60581793149664 5.81330107636588" xyz="0.13574407284830436 0.4047597268960249 0.2676418626192122"/>
	</joint>
</robot>
