<?xml version="1.0"?><robot name="pepe">
	<link name="0">
		<visual>
			<geometry>
				<cylinder length="0.310487813799759" radius="0.9849266278542592"/>
			</geometry>
		</visual>
		<collision>
			<geometry>
				<cylinder length="0.310487813799759" radius="0.9849266278542592"/>
			</geometry>
		</collision>
		<inertial>
			<mass value="0.9462419328123763"/>
			<inertia ixx="0.03" iyy="0.03" izz="0.03" ixy="0" ixz="0" iyx="0"/>
		</inertial>
	</link>
	<link name="11">
		<visual>
			<geometry>
				<cylinder length="0.26257222081243037" radius="0.4736101353718284"/>
			</geometry>
		</visual>
		<collision>
			<geometry>
				<cylinder length="0.26257222081243037" radius="0.4736101353718284"/>
			</geometry>
		</collision>
		<inertial>
			<mass value="0.1850293510953993"/>
			<inertia ixx="0.03" iyy="0.03" izz="0.03" ixy="0" ixz="0" iyx="0"/>
		</inertial>
	</link>
	<link name="12">
		<visual>
			<geometry>
				<cylinder length="0.26257222081243037" radius="0.4736101353718284"/>
			</geometry>
		</visual>
		<collision>
			<geometry>
				<cylinder length="0.26257222081243037" radius="0.4736101353718284"/>
			</geometry>
		</collision>
		<inertial>
			<mass value="0.1850293510953993"/>
			<inertia ixx="0.03" iyy="0.03" izz="0.03" ixy="0" ixz="0" iyx="0"/>
		</inertial>
	</link>
	<link name="23">
		<visual>
			<geometry>
				<cylinder length="0.3983223273810381" radius="0.9662059165895178"/>
			</geometry>
		</visual>
		<collision>
			<geometry>
				<cylinder length="0.3983223273810381" radius="0.9662059165895178"/>
			</geometry>
		</collision>
		<inertial>
			<mass value="1.1682180405632983"/>
			<inertia ixx="0.03" iyy="0.03" izz="0.03" ixy="0" ixz="0" iyx="0"/>
		</inertial>
	</link>
	<link name="24">
		<visual>
			<geometry>
				<cylinder length="0.3983223273810381" radius="0.9662059165895178"/>
			</geometry>
		</visual>
		<collision>
			<geometry>
				<cylinder length="0.3983223273810381" radius="0.9662059165895178"/>
			</geometry>
		</collision>
		<inertial>
			<mass value="1.1682180405632983"/>
			<inertia ixx="0.03" iyy="0.03" izz="0.03" ixy="0" ixz="0" iyx="0"/>
		</inertial>
	</link>
	<link name="25">
		<visual>
			<geometry>
				<cylinder length="0.3983223273810381" radius="0.9662059165895178"/>
			</geometry>
		</visual>
		<collision>
			<geometry>
				<cylinder length="0.3983223273810381" radius="0.9662059165895178"/>
			</geometry>
		</collision>
		<inertial>
			<mass value="1.1682180405632983"/>
			<inertia ixx="0.03" iyy="0.03" izz="0.03" ixy="0" ixz="0" iyx="0"/>
		</inertial>
	</link>
	<joint name="11_to_0" type="revolute">
		<parent link="0"/>
		<child link="11"/>
		<axis xyz="1 0 0"/>
		<limit effort="1" upper="-3.1415" lower="3.1415" velocity="1"/>
		<origin rpy="4.049544802318213 0.9179962420302378 0.11056050839380897" xyz="0.05680210507978456 0.3356216298661001 0.27578599177140994"/>
	</joint>
	<joint name="12_to_0" type="revolute">
		<parent link="0"/>
		<child link="12"/>
		<axis xyz="1 0 0"/>
		<limit effort="1" upper="-3.1415" lower="3.1415" velocity="1"/>
		<origin rpy="6.074317203477319 0.9179962420302378 0.11056050839380897" xyz="0.05680210507978456 0.3356216298661001 0.27578599177140994"/>
	</joint>
	<joint name="23_to_0" type="revolute">
		<parent link="0"/>
		<child link="23"/>
		<axis xyz="0 1 0"/>
		<limit effort="1" upper="-3.1415" lower="3.1415" velocity="1"/>
		<origin rpy="3.7924875291275195 0.5557765427429728 4.815885059667454" xyz="0.7263793094094134 0.5658856207331799 0.9138623024577768"/>
	</joint>
	<joint name="24_to_0" type="revolute">
		<parent link="0"/>
		<child link="24"/>
		<axis xyz="0 1 0"/>
		<limit effort="1" upper="-3.1415" lower="3.1415" velocity="1"/>
		<origin rpy="4.740609411409399 0.5557765427429728 4.815885059667454" xyz="0.7263793094094134 0.5658856207331799 0.9138623024577768"/>
	</joint>
	<joint name="25_to_0" type="revolute">
		<parent link="0"/>
		<child link="25"/>
		<axis xyz="0 1 0"/>
		<limit effort="1" upper="-3.1415" lower="3.1415" velocity="1"/>
		<origin rpy="5.688731293691279 0.5557765427429728 4.815885059667454" xyz="0.7263793094094134 0.5658856207331799 0.9138623024577768"/>
	</joint>
</robot>
